Workbook

Sheet Index
C2: Range Index
A3: Faktor | B3: Bobot | C3: Min | D3: Max | E3: point per derajat index
A4: Nilai Dasar | B4: 0 | C4: 0 | D4: =MAX('perhitungan individu'!$D$32:$D$501)/100000 -> 80 | E4: =B4/D4 -> 0
A5: =C14 -> Lama Kerja | B5: 0 | C5: 0 | D5: =MAX(D15:D41) -> 15 | E5: =B5/D5 -> 0
A6: =E14 -> Kompetensi | B6: 10 | C6: 1 | D6: =MAX(F15:F41) -> 10 | E6: =B6/D6 -> 1
A7: =G14 -> Risiko | B7: 12 | C7: 1 | D7: =MAX(I15:I41) -> 6 | E7: =B7/D7 -> 2
A8: =J14 -> Emergency | B8: 12 | C8: 1 | D8: =MAX(L15:L41) -> 6 | E8: =B8/D8 -> 2
A9: =M14 -> Posisi | B9: 15 | C9: 1 | D9: =MAX(N15:N41) -> 8 | E9: =B9/D9 -> 1.875
A10: Point Kinerja Unit | B10: 0 | C10: 3 | D10: 5 | E10: =B10/D10 -> 0
A11: Kehadiran Individu | B11: 20 | C11: 0 | D11: 100 | E11: =B11/D11 -> 0.2
B12: =SUM(B4:B11) -> 69
A14: Nilai Dasar | C14: Lama Kerja | D14: Index | E14: Kompetensi | F14: Index | G14: Risiko | I14: Index | J14: Emergency | L14: Index | M14: Posisi | N14: Index | O14: performance
A15: Gaji Pokok /100.000 | C15: 0 <n < 2 | D15: 0 | E15: SD | F15: 1 | G15: Grade 1 | H15: Kantor | I15: 1 | J15: Grade 1 | K15: Kantor | L15: 1 | M15: Tidak memiliki jabatan | N15: 1
C16: 2 < n < 4 | D16: 1 | E16: SMP | F16: 2 | G16: Grade 1 | H16: MR | I16: 1 | J16: Grade 1 | K16: MR | L16: 1 | M16: Kepala Ruangan | N16: 2
C17: 4 < n < 6 | D17: 2 | E17: SMU/SMK | F17: 3 | G17: Grade 1 | H17: Gizi | I17: 1 | J17: Grade 1 | K17: Gizi | L17: 1 | M17: Kepala Sub Bidang | N17: 2
C18: 6 < n < 8 | D18: 3 | E18: D1 | F18: 4 | G18: Grade 1 | H18: Farmasi | I18: 1 | J18: Grade 1 | K18: Farmasi | L18: 1 | M18: Kepala Sub Bagian | N18: 2
C19: 8 < n < 10 | D19: 4 | E19: D3 | F19: 5 | G19: Grade 2 | H19: IGD | I19: 2 | J19: Grade 2 | K19: Rawat Jalan | L19: 2 | M19: Ketua Panitia | N19: 2
C20: 10 < n < 12 | D20: 5 | E20: D4 | F20: 6 | G20: Grade 2 | H20: Rawat Jalan | I20: 2 | J20: Grade 2 | K20: Fisioterapi | L20: 2 | M20: Kepala Instalasi | N20: 4
C21: 12 < n < 14 | D21: 6 | E21: S1 | F21: 7 | G21: Grade 2 | H21: Fisioterapi | I21: 2 | J21: Grade 2 | K21: Kamar Jenazah | L21: 2 | M21: Kepala Bagian | N21: 4
C22: 14 < n < 16 | D22: 7 | E22: S2/Dokter Umum/Dokter Gigi/Apoteker/NERS | F22: 8 | G22: Grade 2 | H22: Kamar Jenazah | I22: 2 | J22: Grade 3 | K22: R. Perawatan Mawar | L22: 4 | M22: Kepala Bidang | N22: 4
C23: 16 < n < 18 | D23: 8 | E23: S3/Dokter Spesialis | F23: 9 | G23: Grade 3 | H23: R. Perawatan Mawar | I23: 4 | J23: Grade 3 | K23: R. Perawatan Melati | L23: 4 | M23: Ketua SPI | N23: 4
C24: 18 < n < 20 | D24: 9 | E24: Dokter Subspesialis | F24: 10 | G24: Grade 3 | H24: R. Perawatan Melati | I24: 4 | J24: Grade 3 | K24: R. Perawatan Kenanga | L24: 4 | M24: Komite Medik | N24: 6
C25: 20 < n < 22 | D25: 10 | G25: Grade 3 | H25: R. Perawatan Kenanga | I25: 4 | J25: Grade 3 | K25: R. Perawatan Bedah | L25: 4 | M25: Direktur | N25: 8
C26: 22 < n < 24 | D26: 11 | G26: Grade 3 | H26: R. Perawatan Bedah | I26: 4 | J26: Grade 3 | K26: Laboratorium | L26: 4
C27: 24 < n < 26 | D27: 12 | G27: Grade 3 | H27: Laboratorium | I27: 4 | J27: Grade 3 | K27: Radiologi | L27: 4
C28: 26 < n < 28 | D28: 13 | G28: Grade 3 | H28: Radiologi | I28: 4 | J28: Grade 4 | K28: ICU | L28: 6
C29: 28 < n < 30 | D29: 14 | G29: Grade 4 | H29: ICU | I29: 6 | J29: Grade 4 | K29: OK | L29: 6
C30: 30 < n | D30: 15 | G30: Grade 4 | H30: OK | I30: 6 | J30: Grade 4 | K30: Kamar Bersalin | L30: 6
G31: Grade 4 | H31: Kamar Bersalin | I31: 6 | J31: Grade 4 | K31: IGD | L31: 6

Sheet Kinera Unit Kerja
B3: Unit Kerja | C3: Indikator | D3: Target | E3: Realisasi | F3: % dari target | G3: point
B4: =Index!H15 -> Kantor | G4: =AVERAGE(G5:G20) -> 4.0588235
B5: =Index!H16 -> MR | C5: jml. pasien | D5: 100 | E5: 70 | F5: =IF(E5=0,0,E5/D5)*100 -> 70 | G5: =((Index!D$10-Index!C$10)/(MAX(F$5:F$20)-MIN(F$5:F$20))*(F5-MIN(F$5:F$20)))+Index!C$10 -> 3.9411765
B6: =Index!H17 -> Gizi | C6: jml. porsi | D6: 100 | E6: 110 | F6: =IF(E6=0,0,E6/D6)*100 -> 110 | G6: =((Index!D$10-Index!C$10)/(MAX(F$5:F$20)-MIN(F$5:F$20))*(F6-MIN(F$5:F$20)))+Index!C$10 -> 4.8823529
B7: =Index!H18 -> Farmasi | C7: jml. lembar resep | D7: 100 | E7: 70 | F7: =IF(E7=0,0,E7/D7)*100 -> 70 | G7: =((Index!D$10-Index!C$10)/(MAX(F$5:F$20)-MIN(F$5:F$20))*(F7-MIN(F$5:F$20)))+Index!C$10 -> 3.9411765
B8: =Index!H19 -> IGD | C8: jml. pasien | D8: 100 | E8: 70 | F8: =IF(E8=0,0,E8/D8)*100 -> 70 | G8: =((Index!D$10-Index!C$10)/(MAX(F$5:F$20)-MIN(F$5:F$20))*(F8-MIN(F$5:F$20)))+Index!C$10 -> 3.9411765
B9: =Index!H20 -> Rawat Jalan | C9: jml. pasien | D9: 100 | E9: 70 | F9: =IF(E9=0,0,E9/D9)*100 -> 70 | G9: =((Index!D$10-Index!C$10)/(MAX(F$5:F$20)-MIN(F$5:F$20))*(F9-MIN(F$5:F$20)))+Index!C$10 -> 3.9411765
B10: =Index!H21 -> Fisioterapi | C10: jml. pasien | D10: 100 | E10: 30 | F10: =IF(E10=0,0,E10/D10)*100 -> 30 | G10: =((Index!D$10-Index!C$10)/(MAX(F$5:F$20)-MIN(F$5:F$20))*(F10-MIN(F$5:F$20)))+Index!C$10 -> 3
B11: =Index!H22 -> Kamar Jenazah | C11: jml. pasien | D11: 100 | E11: 60 | F11: =IF(E11=0,0,E11/D11)*100 -> 60 | G11: =((Index!D$10-Index!C$10)/(MAX(F$5:F$20)-MIN(F$5:F$20))*(F11-MIN(F$5:F$20)))+Index!C$10 -> 3.7058824
B12: =Index!H23 -> R. Perawatan Mawar | C12: jml. hari rawat | D12: 100 | E12: 115 | F12: =IF(E12=0,0,E12/D12)*100 -> 115 | G12: =((Index!D$10-Index!C$10)/(MAX(F$5:F$20)-MIN(F$5:F$20))*(F12-MIN(F$5:F$20)))+Index!C$10 -> 5
B13: =Index!H24 -> R. Perawatan Melati | C13: jml. hari rawat | D13: 100 | E13: 70 | F13: =IF(E13=0,0,E13/D13)*100 -> 70 | G13: =((Index!D$10-Index!C$10)/(MAX(F$5:F$20)-MIN(F$5:F$20))*(F13-MIN(F$5:F$20)))+Index!C$10 -> 3.9411765
B14: =Index!H25 -> R. Perawatan Kenanga | C14: jml. hari rawat | D14: 100 | E14: 70 | F14: =IF(E14=0,0,E14/D14)*100 -> 70 | G14: =((Index!D$10-Index!C$10)/(MAX(F$5:F$20)-MIN(F$5:F$20))*(F14-MIN(F$5:F$20)))+Index!C$10 -> 3.9411765
B15: =Index!H26 -> R. Perawatan Bedah | C15: jml. hari rawat | D15: 100 | E15: 70 | F15: =IF(E15=0,0,E15/D15)*100 -> 70 | G15: =((Index!D$10-Index!C$10)/(MAX(F$5:F$20)-MIN(F$5:F$20))*(F15-MIN(F$5:F$20)))+Index!C$10 -> 3.9411765
B16: =Index!H27 -> Laboratorium | C16: jml. pemeriksaan | D16: 100 | E16: 70 | F16: =IF(E16=0,0,E16/D16)*100 -> 70 | G16: =((Index!D$10-Index!C$10)/(MAX(F$5:F$20)-MIN(F$5:F$20))*(F16-MIN(F$5:F$20)))+Index!C$10 -> 3.9411765
... B20: =Index!H31 -> Kamar Bersalin | C20: jml. hari rawat | D20: 100 | E20: 70 | F20: =IF(E20=0,0,E20/D20)*100 -> 70 | G20: =((Index!D$10-Index!C$10)/(MAX(F$5:F$20)-MIN(F$5:F$20))*(F20-MIN(F$5:F$20)))+Index!C$10 -> 3.9411765

Sheet perhitungan individu
E1: Lama Kerja | F1: Pendidikan Akhir | G1: Unit Kerja | H1: Jabatan
E2: =Index!C15 -> 0 <n < 2 | F2: =Index!E15 -> SD | G2: =Index!H15 -> Kantor | H2: =Index!M15 -> Tidak memiliki jabatan
E3: =Index!C16 -> 2 < n < 4 | F3: =Index!E16 -> SMP | G3: =Index!H16 -> MR | H3: =Index!M16 -> Kepala Ruangan
E4: =Index!C17 -> 4 < n < 6 | F4: =Index!E17 -> SMU/SMK | G4: =Index!H17 -> Gizi | H4: =Index!M17 -> Kepala Sub Bidang
E5: =Index!C18 -> 6 < n < 8 | F5: =Index!E18 -> D1 | G5: =Index!H18 -> Farmasi | H5: =Index!M18 -> Kepala Sub Bagian
E6: =Index!C19 -> 8 < n < 10 | F6: =Index!E19 -> D3 | G6: =Index!H19 -> IGD | H6: =Index!M19 -> Ketua Panitia
E7: =Index!C20 -> 10 < n < 12 | F7: =Index!E20 -> D4 | G7: =Index!H20 -> Rawat Jalan | H7: =Index!M20 -> Kepala Instalasi
E8: =Index!C21 -> 12 < n < 14 | F8: =Index!E21 -> S1 | G8: =Index!H21 -> Fisioterapi | H8: =Index!M21 -> Kepala Bagian
E9: =Index!C22 -> 14 < n < 16 | F9: =Index!E22 -> S2/Dokter Umum/Dokter Gigi/Apoteker/NERS | G9: =Index!H22 -> Kamar Jenazah | H9: =Index!M22 -> Kepala Bidang
E10: =Index!C23 -> 16 < n < 18 | F10: =Index!E23 -> S3/Dokter Spesialis | G10: =Index!H23 -> R. Perawatan Mawar | H10: =Index!M23 -> Ketua SPI
E11: =Index!C24 -> 18 < n < 20 | F11: =Index!E24 -> Dokter Subspesialis | G11: =Index!H24 -> R. Perawatan Melati | H11: =Index!M24 -> Komite Medik
E12: =Index!C25 -> 20 < n < 22 | F12: =Index!E25 -> 0 | G12: =Index!H25 -> R. Perawatan Kenanga | H12: =Index!M25 -> Direktur
E13: =Index!C26 -> 22 < n < 24 | F13: =Index!E26 -> 0 | G13: =Index!H26 -> R. Perawatan Bedah | H13: =Index!M26 -> 0
... E25: =Index!C38 -> 0 | F25: =Index!E38 -> 0 | G25: =Index!H38 -> 0 | H25: =Index!M38 -> 0
A26: Tanggal Perhitungan
A28: Anggaran Yang Dibagikan (Rp)
B29: 3000000 | J29: Point Index | R29: =SUM(R32:R501) -> 397.125 | S29: =SUM(S32:S501) -> 3000000
J30: ="max = "&Index!$B4 -> max = 0 | K30: ="max = "&Index!$B5 -> max = 0 | L30: ="max = "&Index!$B6 -> max = 10 | M30: ="max = "&Index!$B7 -> max = 12 | N30: ="max = "&Index!$B8 -> max = 12 | O30: ="max = "&Index!$B9 -> max = 15 | P30: ="max = "&Index!$B10 -> max = 0 | Q30: ="max = "&Index!$B11 -> max = 20 | R30: ="max = "&Index!$B12 -> max = 69
A31: No | B31: Nama | C31: Mulai Kerja | D31: Gaji Pokok | E31: Lama Kerja | F31: Pendidikan Akhir | G31: Unit Kerja | H31: Jabatan | I31: Kehadiran Individu | J31: Nilai Dasar | K31: Lama Kerja | L31: Kompetensi | M31: Risiko | N31: Emergency | O31: Posisi | P31: Performace Unit Kerja | Q31: Kehadiran Individu | R31: Total Point | S31: Rp yang dibagikan
B32: a | D32: 8000000 | E32: 2 < n < 4 | F32: S2/Dokter Umum/Dokter Gigi/Apoteker/NERS | G32: Kantor | H32: Direktur | I32: 100 | J32: =(D32/100000)*Index!$E$4 -> 0 | K32: =SUMIF(Index!$C$15:$C$40,'perhitungan individu'!E32,Index!$D$15:$D$40)*Index!$E$5 -> 0 | L32: =SUMIF(Index!$E$15:$E$40,'perhitungan individu'!F32,Index!F$15:F$40)*Index!$E$6 -> 8 | M32: =SUMIF(Index!$H$15:$H$40,'perhitungan individu'!$G32,Index!$I$15:$I$40)*Index!$E$7 -> 2 | N32: =SUMIF(Index!$K$15:$K$40,'perhitungan individu'!$G32,Index!$L$15:$L$40)*Index!$E$8 -> 2 | O32: =SUMIF(Index!$M$15:$M$40,'perhitungan individu'!H32,Index!$N$15:$N$40)*Index!$E$9 -> 15 | P32: =SUMIF('Kinera Unit Kerja'!$B$4:$B$20,'perhitungan individu'!$G32,'Kinera Unit Kerja'!$G$4:$G$20)*Index!$E$10 -> 0 | Q32: =I32*Index!$E$11 -> 20 | R32: =SUM(J32:Q32) -> 47 | S32: =$B$29/$R$29*$R32 -> 355051.94
B33: b | D33: 900000 | E33: 14 < n < 16 | F33: SMP | G33: Kantor | H33: Tidak memiliki jabatan | I33: 100 | J33: =(D33/100000)*Index!$E$4 -> 0 | K33: =SUMIF(Index!$C$15:$C$40,'perhitungan individu'!E33,Index!$D$15:$D$40)*Index!$E$5 -> 0 | L33: =SUMIF(Index!$E$15:$E$40,'perhitungan individu'!F33,Index!F$15:F$40)*Index!$E$6 -> 2 | M33: =SUMIF(Index!$H$15:$H$40,'perhitungan individu'!$G33,Index!$I$15:$I$40)*Index!$E$7 -> 2 | N33: =SUMIF(Index!$K$15:$K$40,'perhitungan individu'!$G33,Index!$L$15:$L$40)*Index!$E$8 -> 2 | O33: =SUMIF(Index!$M$15:$M$40,'perhitungan individu'!H33,Index!$N$15:$N$40)*Index!$E$9 -> 1.875 | P33: =SUMIF('Kinera Unit Kerja'!$B$4:$B$20,'perhitungan individu'!$G33,'Kinera Unit Kerja'!$G$4:$G$20)*Index!$E$10 -> 0 | Q33: =I33*Index!$E$11 -> 20 | R33: =SUM(J33:Q33) -> 27.875 | S33: =$B$29/$R$29*$R33 -> 210576.02
B34: c | D34: 2500000 | E34: 4 < n < 6 | F34: S1 | G34: Kantor | H34: Kepala Bagian | I34: 100 | J34: =(D34/100000)*Index!$E$4 -> 0 | K34: =SUMIF(Index!$C$15:$C$40,'perhitungan individu'!E34,Index!$D$15:$D$40)*Index!$E$5 -> 0 | L34: =SUMIF(Index!$E$15:$E$40,'perhitungan individu'!F34,Index!F$15:F$40)*Index!$E$6 -> 7 | M34: =SUMIF(Index!$H$15:$H$40,'perhitungan individu'!$G34,Index!$I$15:$I$40)*Index!$E$7 -> 2 | N34: =SUMIF(Index!$K$15:$K$40,'perhitungan individu'!$G34,Index!$L$15:$L$40)*Index!$E$8 -> 2 | O34: =SUMIF(Index!$M$15:$M$40,'perhitungan individu'!H34,Index!$N$15:$N$40)*Index!$E$9 -> 7.5 | P34: =SUMIF('Kinera Unit Kerja'!$B$4:$B$20,'perhitungan individu'!$G34,'Kinera Unit Kerja'!$G$4:$G$20)*Index!$E$10 -> 0 | Q34: =I34*Index!$E$11 -> 20 | R34: =SUM(J34:Q34) -> 38.5 | S34: =$B$29/$R$29*$R34 -> 290840.42
B35: d | D35: 2500000 | E35: 4 < n < 6 | F35: S1 | G35: IGD | H35: Kepala Ruangan | I35: 100 | J35: =(D35/100000)*Index!$E$4 -> 0 | K35: =SUMIF(Index!$C$15:$C$40,'perhitungan individu'!E35,Index!$D$15:$D$40)*Index!$E$5 -> 0 | L35: =SUMIF(Index!$E$15:$E$40,'perhitungan individu'!F35,Index!F$15:F$40)*Index!$E$6 -> 7 | M35: =SUMIF(Index!$H$15:$H$40,'perhitungan individu'!$G35,Index!$I$15:$I$40)*Index!$E$7 -> 4 | N35: =SUMIF(Index!$K$15:$K$40,'perhitungan individu'!$G35,Index!$L$15:$L$40)*Index!$E$8 -> 12 | O35: =SUMIF(Index!$M$15:$M$40,'perhitungan individu'!H35,Index!$N$15:$N$40)*Index!$E$9 -> 3.75 | P35: =SUMIF('Kinera Unit Kerja'!$B$4:$B$20,'perhitungan individu'!$G35,'Kinera Unit Kerja'!$G$4:$G$20)*Index!$E$10 -> 0 | Q35: =I35*Index!$E$11 -> 20 | R35: =SUM(J35:Q35) -> 46.75 | S35: =$B$29/$R$29*$R35 -> 353163.36
B36: e | D36: 2500000 | E36: 4 < n < 6 | F36: S1 | G36: ICU | H36: Tidak memiliki jabatan | I36: 100 | J36: =(D36/100000)*Index!$E$4 -> 0 | K36: =SUMIF(Index!$C$15:$C$40,'perhitungan individu'!E36,Index!$D$15:$D$40)*Index!$E$5 -> 0 | L36: =SUMIF(Index!$E$15:$E$40,'perhitungan individu'!F36,Index!F$15:F$40)*Index!$E$6 -> 7 | M36: =SUMIF(Index!$H$15:$H$40,'perhitungan individu'!$G36,Index!$I$15:$I$40)*Index!$E$7 -> 12 | N36: =SUMIF(Index!$K$15:$K$40,'perhitungan individu'!$G36,Index!$L$15:$L$40)*Index!$E$8 -> 12 | O36: =SUMIF(Index!$M$15:$M$40,'perhitungan individu'!H36,Index!$N$15:$N$40)*Index!$E$9 -> 1.875 | P36: =SUMIF('Kinera Unit Kerja'!$B$4:$B$20,'perhitungan individu'!$G36,'Kinera Unit Kerja'!$G$4:$G$20)*Index!$E$10 -> 0 | Q36: =I36*Index!$E$11 -> 20 | R36: =SUM(J36:Q36) -> 52.875 | S36: =$B$29/$R$29*$R36 -> 399433.43
B37: f | D37: 2500000 | E37: 4 < n < 6 | F37: S1 | G37: ICU | H37: Kepala Ruangan | I37: 70 | J37: =(D37/100000)*Index!$E$4 -> 0 | K37: =SUMIF(Index!$C$15:$C$40,'perhitungan individu'!E37,Index!$D$15:$D$40)*Index!$E$5 -> 0 | L37: =SUMIF(Index!$E$15:$E$40,'perhitungan individu'!F37,Index!F$15:F$40)*Index!$E$6 -> 7 | M37: =SUMIF(Index!$H$15:$H$40,'perhitungan individu'!$G37,Index!$I$15:$I$40)*Index!$E$7 -> 12 | N37: =SUMIF(Index!$K$15:$K$40,'perhitungan individu'!$G37,Index!$L$15:$L$40)*Index!$E$8 -> 12 | O37: =SUMIF(Index!$M$15:$M$40,'perhitungan individu'!H37,Index!$N$15:$N$40)*Index!$E$9 -> 3.75 | P37: =SUMIF('Kinera Unit Kerja'!$B$4:$B$20,'perhitungan individu'!$G37,'Kinera Unit Kerja'!$G$4:$G$20)*Index!$E$10 -> 0 | Q37: =I37*Index!$E$11 -> 14 | R37: =SUM(J37:Q37) -> 48.75 | S37: =$B$29/$R$29*$R37 -> 368271.95
B38: g | D38: 900000 | E38: 30 < n | F38: SMP | G38: Kantor | H38: Tidak memiliki jabatan | I38: 100 | J38: =(D38/100000)*Index!$E$4 -> 0 | K38: =SUMIF(Index!$C$15:$C$40,'perhitungan individu'!E38,Index!$D$15:$D$40)*Index!$E$5 -> 0 | L38: =SUMIF(Index!$E$15:$E$40,'perhitungan individu'!F38,Index!F$15:F$40)*Index!$E$6 -> 2 | M38: =SUMIF(Index!$H$15:$H$40,'perhitungan individu'!$G38,Index!$I$15:$I$40)*Index!$E$7 -> 2 | N38: =SUMIF(Index!$K$15:$K$40,'perhitungan individu'!$G38,Index!$L$15:$L$40)*Index!$E$8 -> 2 | O38: =SUMIF(Index!$M$15:$M$40,'perhitungan individu'!H38,Index!$N$15:$N$40)*Index!$E$9 -> 1.875 | P38: =SUMIF('Kinera Unit Kerja'!$B$4:$B$20,'perhitungan individu'!$G38,'Kinera Unit Kerja'!$G$4:$G$20)*Index!$E$10 -> 0 | Q38: =I38*Index!$E$11 -> 20 | R38: =SUM(J38:Q38) -> 27.875 | S38: =$B$29/$R$29*$R38 -> 210576.02
B39: h | D39: 2500000 | E39: 20 < n < 22 | F39: S1 | G39: Rawat Jalan | H39: Kepala Bagian | I39: 80 | J39: =(D39/100000)*Index!$E$4 -> 0 | K39: =SUMIF(Index!$C$15:$C$40,'perhitungan individu'!E39,Index!$D$15:$D$40)*Index!$E$5 -> 0 | L39: =SUMIF(Index!$E$15:$E$40,'perhitungan individu'!F39,Index!F$15:F$40)*Index!$E$6 -> 7 | M39: =SUMIF(Index!$H$15:$H$40,'perhitungan individu'!$G39,Index!$I$15:$I$40)*Index!$E$7 -> 4 | N39: =SUMIF(Index!$K$15:$K$40,'perhitungan individu'!$G39,Index!$L$15:$L$40)*Index!$E$8 -> 4 | O39: =SUMIF(Index!$M$15:$M$40,'perhitungan individu'!H39,Index!$N$15:$N$40)*Index!$E$9 -> 7.5 | P39: =SUMIF('Kinera Unit Kerja'!$B$4:$B$20,'perhitungan individu'!$G39,'Kinera Unit Kerja'!$G$4:$G$20)*Index!$E$10 -> 0 | Q39: =I39*Index!$E$11 -> 16 | R39: =SUM(J39:Q39) -> 38.5 | S39: =$B$29/$R$29*$R39 -> 290840.42
B40: i | D40: 8000000 | E40: 30 < n | F40: Dokter Subspesialis | G40: OK | H40: Direktur | I40: 100 | J40: =(D40/100000)*Index!$E$4 -> 0 | K40: =SUMIF(Index!$C$15:$C$40,'perhitungan individu'!E40,Index!$D$15:$D$40)*Index!$E$5 -> 0 | L40: =SUMIF(Index!$E$15:$E$40,'perhitungan individu'!F40,Index!F$15:F$40)*Index!$E$6 -> 10 | M40: =SUMIF(Index!$H$15:$H$40,'perhitungan individu'!$G40,Index!$I$15:$I$40)*Index!$E$7 -> 12 | N40: =SUMIF(Index!$K$15:$K$40,'perhitungan individu'!$G40,Index!$L$15:$L$40)*Index!$E$8 -> 12 | O40: =SUMIF(Index!$M$15:$M$40,'perhitungan individu'!H40,Index!$N$15:$N$40)*Index!$E$9 -> 15 | P40: =SUMIF('Kinera Unit Kerja'!$B$4:$B$20,'perhitungan individu'!$G40,'Kinera Unit Kerja'!$G$4:$G$20)*Index!$E$10 -> 0 | Q40: =I40*Index!$E$11 -> 20 | R40: =SUM(J40:Q40) -> 69 | S40: =$B$29/$R$29*$R40 -> 521246.46
J41: =(D41/100000)*Index!$E$4 -> 0 | K41: =SUMIF(Index!$C$15:$C$40,'perhitungan individu'!E41,Index!$D$15:$D$40)*Index!$E$5 -> 0 | L41: =SUMIF(Index!$E$15:$E$40,'perhitungan individu'!F41,Index!F$15:F$40)*Index!$E$6 -> 0 | M41: =SUMIF(Index!$H$15:$H$40,'perhitungan individu'!$G41,Index!$I$15:$I$40)*Index!$E$7 -> 0 | N41: =SUMIF(Index!$K$15:$K$40,'perhitungan individu'!$G41,Index!$L$15:$L$40)*Index!$E$8 -> 0 | O41: =SUMIF(Index!$M$15:$M$40,'perhitungan individu'!H41,Index!$N$15:$N$40)*Index!$E$9 -> 0 | P41: =SUMIF('Kinera Unit Kerja'!$B$4:$B$20,'perhitungan individu'!$G41,'Kinera Unit Kerja'!$G$4:$G$20)*Index!$E$10 -> 0 | Q41: =I41*Index!$E$11 -> 0 | R41: =SUM(J41:Q41) -> 0 | S41: =$B$29/$R$29*$R41 -> 0
J42: =(D42/100000)*Index!$E$4 -> 0 | K42: =SUMIF(Index!$C$15:$C$40,'perhitungan individu'!E42,Index!$D$15:$D$40)*Index!$E$5 -> 0 | L42: =SUMIF(Index!$E$15:$E$40,'perhitungan individu'!F42,Index!F$15:F$40)*Index!$E$6 -> 0 | M42: =SUMIF(Index!$H$15:$H$40,'perhitungan individu'!$G42,Index!$I$15:$I$40)*Index!$E$7 -> 0 | N42: =SUMIF(Index!$K$15:$K$40,'perhitungan individu'!$G42,Index!$L$15:$L$40)*Index!$E$8 -> 0 | O42: =SUMIF(Index!$M$15:$M$40,'perhitungan individu'!H42,Index!$N$15:$N$40)*Index!$E$9 -> 0 | P42: =SUMIF('Kinera Unit Kerja'!$B$4:$B$20,'perhitungan individu'!$G42,'Kinera Unit Kerja'!$G$4:$G$20)*Index!$E$10 -> 0 | Q42: =I42*Index!$E$11 -> 0 | R42: =SUM(J42:Q42) -> 0 | S42: =$B$29/$R$29*$R42 -> 0
J43: =(D43/100000)*Index!$E$4 -> 0 | K43: =SUMIF(Index!$C$15:$C$40,'perhitungan individu'!E43,Index!$D$15:$D$40)*Index!$E$5 -> 0 | L43: =SUMIF(Index!$E$15:$E$40,'perhitungan individu'!F43,Index!F$15:F$40)*Index!$E$6 -> 0 | M43: =SUMIF(Index!$H$15:$H$40,'perhitungan individu'!$G43,Index!$I$15:$I$40)*Index!$E$7 -> 0 | N43: =SUMIF(Index!$K$15:$K$40,'perhitungan individu'!$G43,Index!$L$15:$L$40)*Index!$E$8 -> 0 | O43: =SUMIF(Index!$M$15:$M$40,'perhitungan individu'!H43,Index!$N$15:$N$40)*Index!$E$9 -> 0 | P43: =SUMIF('Kinera Unit Kerja'!$B$4:$B$20,'perhitungan individu'!$G43,'Kinera Unit Kerja'!$G$4:$G$20)*Index!$E$10 -> 0 | Q43: =I43*Index!$E$11 -> 0 | R43: =SUM(J43:Q43) -> 0 | S43: =$B$29/$R$29*$R43 -> 0
J44: =(D44/100000)*Index!$E$4 -> 0 | K44: =SUMIF(Index!$C$15:$C$40,'perhitungan individu'!E44,Index!$D$15:$D$40)*Index!$E$5 -> 0 | L44: =SUMIF(Index!$E$15:$E$40,'perhitungan individu'!F44,Index!F$15:F$40)*Index!$E$6 -> 0 | M44: =SUMIF(Index!$H$15:$H$40,'perhitungan individu'!$G44,Index!$I$15:$I$40)*Index!$E$7 -> 0 | N44: =SUMIF(Index!$K$15:$K$40,'perhitungan individu'!$G44,Index!$L$15:$L$40)*Index!$E$8 -> 0 | O44: =SUMIF(Index!$M$15:$M$40,'perhitungan individu'!H44,Index!$N$15:$N$40)*Index!$E$9 -> 0 | P44: =SUMIF('Kinera Unit Kerja'!$B$4:$B$20,'perhitungan individu'!$G44,'Kinera Unit Kerja'!$G$4:$G$20)*Index!$E$10 -> 0 | Q44: =I44*Index!$E$11 -> 0 | R44: =SUM(J44:Q44) -> 0 | S44: =$B$29/$R$29*$R44 -> 0
J45: =(D45/100000)*Index!$E$4 -> 0 | K45: =SUMIF(Index!$C$15:$C$40,'perhitungan individu'!E45,Index!$D$15:$D$40)*Index!$E$5 -> 0 | L45: =SUMIF(Index!$E$15:$E$40,'perhitungan individu'!F45,Index!F$15:F$40)*Index!$E$6 -> 0 | M45: =SUMIF(Index!$H$15:$H$40,'perhitungan individu'!$G45,Index!$I$15:$I$40)*Index!$E$7 -> 0 | N45: =SUMIF(Index!$K$15:$K$40,'perhitungan individu'!$G45,Index!$L$15:$L$40)*Index!$E$8 -> 0 | O45: =SUMIF(Index!$M$15:$M$40,'perhitungan individu'!H45,Index!$N$15:$N$40)*Index!$E$9 -> 0 | P45: =SUMIF('Kinera Unit Kerja'!$B$4:$B$20,'perhitungan individu'!$G45,'Kinera Unit Kerja'!$G$4:$G$20)*Index!$E$10 -> 0 | Q45: =I45*Index!$E$11 -> 0 | R45: =SUM(J45:Q45) -> 0 | S45: =$B$29/$R$29*$R45 -> 0
J46: =(D46/100000)*Index!$E$4 -> 0 | K46: =SUMIF(Index!$C$15:$C$40,'perhitungan individu'!E46,Index!$D$15:$D$40)*Index!$E$5 -> 0 | L46: =SUMIF(Index!$E$15:$E$40,'perhitungan individu'!F46,Index!F$15:F$40)*Index!$E$6 -> 0 | M46: =SUMIF(Index!$H$15:$H$40,'perhitungan individu'!$G46,Index!$I$15:$I$40)*Index!$E$7 -> 0 | N46: =SUMIF(Index!$K$15:$K$40,'perhitungan individu'!$G46,Index!$L$15:$L$40)*Index!$E$8 -> 0 | O46: =SUMIF(Index!$M$15:$M$40,'perhitungan individu'!H46,Index!$N$15:$N$40)*Index!$E$9 -> 0 | P46: =SUMIF('Kinera Unit Kerja'!$B$4:$B$20,'perhitungan individu'!$G46,'Kinera Unit Kerja'!$G$4:$G$20)*Index!$E$10 -> 0 | Q46: =I46*Index!$E$11 -> 0 | R46: =SUM(J46:Q46) -> 0 | S46: =$B$29/$R$29*$R46 -> 0
J47: =(D47/100000)*Index!$E$4 -> 0 | K47: =SUMIF(Index!$C$15:$C$40,'perhitungan individu'!E47,Index!$D$15:$D$40)*Index!$E$5 -> 0 | L47: =SUMIF(Index!$E$15:$E$40,'perhitungan individu'!F47,Index!F$15:F$40)*Index!$E$6 -> 0 | M47: =SUMIF(Index!$H$15:$H$40,'perhitungan individu'!$G47,Index!$I$15:$I$40)*Index!$E$7 -> 0 | N47: =SUMIF(Index!$K$15:$K$40,'perhitungan individu'!$G47,Index!$L$15:$L$40)*Index!$E$8 -> 0 | O47: =SUMIF(Index!$M$15:$M$40,'perhitungan individu'!H47,Index!$N$15:$N$40)*Index!$E$9 -> 0 | P47: =SUMIF('Kinera Unit Kerja'!$B$4:$B$20,'perhitungan individu'!$G47,'Kinera Unit Kerja'!$G$4:$G$20)*Index!$E$10 -> 0 | Q47: =I47*Index!$E$11 -> 0 | R47: =SUM(J47:Q47) -> 0 | S47: =$B$29/$R$29*$R47 -> 0
J48: =(D48/100000)*Index!$E$4 -> 0 | K48: =SUMIF(Index!$C$15:$C$40,'perhitungan individu'!E48,Index!$D$15:$D$40)*Index!$E$5 -> 0 | L48: =SUMIF(Index!$E$15:$E$40,'perhitungan individu'!F48,Index!F$15:F$40)*Index!$E$6 -> 0 | M48: =SUMIF(Index!$H$15:$H$40,'perhitungan individu'!$G48,Index!$I$15:$I$40)*Index!$E$7 -> 0 | N48: =SUMIF(Index!$K$15:$K$40,'perhitungan individu'!$G48,Index!$L$15:$L$40)*Index!$E$8 -> 0 | O48: =SUMIF(Index!$M$15:$M$40,'perhitungan individu'!H48,Index!$N$15:$N$40)*Index!$E$9 -> 0 | P48: =SUMIF('Kinera Unit Kerja'!$B$4:$B$20,'perhitungan individu'!$G48,'Kinera Unit Kerja'!$G$4:$G$20)*Index!$E$10 -> 0 | Q48: =I48*Index!$E$11 -> 0 | R48: =SUM(J48:Q48) -> 0 | S48: =$B$29/$R$29*$R48 -> 0
J49: =(D49/100000)*Index!$E$4 -> 0 | K49: =SUMIF(Index!$C$15:$C$40,'perhitungan individu'!E49,Index!$D$15:$D$40)*Index!$E$5 -> 0 | L49: =SUMIF(Index!$E$15:$E$40,'perhitungan individu'!F49,Index!F$15:F$40)*Index!$E$6 -> 0 | M49: =SUMIF(Index!$H$15:$H$40,'perhitungan individu'!$G49,Index!$I$15:$I$40)*Index!$E$7 -> 0 | N49: =SUMIF(Index!$K$15:$K$40,'perhitungan individu'!$G49,Index!$L$15:$L$40)*Index!$E$8 -> 0 | O49: =SUMIF(Index!$M$15:$M$40,'perhitungan individu'!H49,Index!$N$15:$N$40)*Index!$E$9 -> 0 | P49: =SUMIF('Kinera Unit Kerja'!$B$4:$B$20,'perhitungan individu'!$G49,'Kinera Unit Kerja'!$G$4:$G$20)*Index!$E$10 -> 0 | Q49: =I49*Index!$E$11 -> 0 | R49: =SUM(J49:Q49) -> 0 | S49: =$B$29/$R$29*$R49 -> 0
J50: =(D50/100000)*Index!$E$4 -> 0 | K50: =SUMIF(Index!$C$15:$C$40,'perhitungan individu'!E50,Index!$D$15:$D$40)*Index!$E$5 -> 0 | L50: =SUMIF(Index!$E$15:$E$40,'perhitungan individu'!F50,Index!F$15:F$40)*Index!$E$6 -> 0 | M50: =SUMIF(Index!$H$15:$H$40,'perhitungan individu'!$G50,Index!$I$15:$I$40)*Index!$E$7 -> 0 | N50: =SUMIF(Index!$K$15:$K$40,'perhitungan individu'!$G50,Index!$L$15:$L$40)*Index!$E$8 -> 0 | O50: =SUMIF(Index!$M$15:$M$40,'perhitungan individu'!H50,Index!$N$15:$N$40)*Index!$E$9 -> 0 | P50: =SUMIF('Kinera Unit Kerja'!$B$4:$B$20,'perhitungan individu'!$G50,'Kinera Unit Kerja'!$G$4:$G$20)*Index!$E$10 -> 0 | Q50: =I50*Index!$E$11 -> 0 | R50: =SUM(J50:Q50) -> 0 | S50: =$B$29/$R$29*$R50 -> 0
J51: =(D51/100000)*Index!$E$4 -> 0 | K51: =SUMIF(Index!$C$15:$C$40,'perhitungan individu'!E51,Index!$D$15:$D$40)*Index!$E$5 -> 0 | L51: =SUMIF(Index!$E$15:$E$40,'perhitungan individu'!F51,Index!F$15:F$40)*Index!$E$6 -> 0 | M51: =SUMIF(Index!$H$15:$H$40,'perhitungan individu'!$G51,Index!$I$15:$I$40)*Index!$E$7 -> 0 | N51: =SUMIF(Index!$K$15:$K$40,'perhitungan individu'!$G51,Index!$L$15:$L$40)*Index!$E$8 -> 0 | O51: =SUMIF(Index!$M$15:$M$40,'perhitungan individu'!H51,Index!$N$15:$N$40)*Index!$E$9 -> 0 | P51: =SUMIF('Kinera Unit Kerja'!$B$4:$B$20,'perhitungan individu'!$G51,'Kinera Unit Kerja'!$G$4:$G$20)*Index!$E$10 -> 0 | Q51: =I51*Index!$E$11 -> 0 | R51: =SUM(J51:Q51) -> 0 | S51: =$B$29/$R$29*$R51 -> 0
J52: =(D52/100000)*Index!$E$4 -> 0 | K52: =SUMIF(Index!$C$15:$C$40,'perhitungan individu'!E52,Index!$D$15:$D$40)*Index!$E$5 -> 0 | L52: =SUMIF(Index!$E$15:$E$40,'perhitungan individu'!F52,Index!F$15:F$40)*Index!$E$6 -> 0 | M52: =SUMIF(Index!$H$15:$H$40,'perhitungan individu'!$G52,Index!$I$15:$I$40)*Index!$E$7 -> 0 | N52: =SUMIF(Index!$K$15:$K$40,'perhitungan individu'!$G52,Index!$L$15:$L$40)*Index!$E$8 -> 0 | O52: =SUMIF(Index!$M$15:$M$40,'perhitungan individu'!H52,Index!$N$15:$N$40)*Index!$E$9 -> 0 | P52: =SUMIF('Kinera Unit Kerja'!$B$4:$B$20,'perhitungan individu'!$G52,'Kinera Unit Kerja'!$G$4:$G$20)*Index!$E$10 -> 0 | Q52: =I52*Index!$E$11 -> 0 | R52: =SUM(J52:Q52) -> 0 | S52: =$B$29/$R$29*$R52 -> 0
...
